<?xml version="1.0"?>
<sdf version="1.9">
  <model name="gimbal">

    <!-- Gimbal base -->
    <link name="base_link">
      <gravity>0</gravity>
      <pose>0.0 0.0 0.0 0.0 0.0 0.0</pose>

      <inertial>
        <inertia>
          <ixx>0.032</ixx>
          <ixy>0</ixy>
          <ixz>0</ixz>
          <iyy>0.032</iyy>
          <iyz>0</iyz>
          <izz>0.00012</izz>
        </inertia>
        <mass>0.200</mass>
      </inertial>

      <visual name="visual">
        <geometry>
          <box>
            <size>0.05 0.05 0.05</size>
          </box>
        </geometry>
      </visual>

      <collision name="collision">
        <geometry>
          <box>
            <size>0.05 0.05 0.05</size>
          </box>
        </geometry>
      </collision>
    </link>

    <!-- camera0 -->
    <link name="camera0">
      <gravity>0</gravity>
      <pose>0.0 0.0 0.1 0.0 0.0 0.0</pose>

      <inertial>
        <inertia>
          <ixx>0.032</ixx>
          <ixy>0</ixy>
          <ixz>0</ixz>
          <iyy>0.032</iyy>
          <iyz>0</iyz>
          <izz>0.00012</izz>
        </inertia>
        <mass>0.08</mass>
      </inertial>

      <visual name="visual">
        <pose>0.0 0.0 0.0 0 0 0</pose>
        <geometry>
          <box>
            <size>0.05 0.03 0.03</size>
          </box>
        </geometry>
      </visual>

      <collision name="collision">
        <pose>0.0 0.0 0.0 0 0 0</pose>
        <geometry>
          <box>
            <size>0.05 0.03 0.03</size>
          </box>
        </geometry>
      </collision>

      <sensor name="camera0" type="camera">
        <topic>/gimbal/camera0</topic>
        <camera>
          <horizontal_fov>1.047</horizontal_fov>
          <image>
            <width>640</width>
            <height>640</height>
          </image>
        </camera>

        <always_on>1</always_on>
        <update_rate>20</update_rate>
        <visualize>true</visualize>
      </sensor>
    </link>

    <joint name="world_fixed" type="fixed">
      <parent>world</parent>
      <child>base_link</child>
    </joint>

    <!-- Yaw joint -->
    <joint name="joint_yaw" type="revolute">
      <pose>0 0 0 0 0 0</pose>
      <parent>base_link</parent>
      <child>camera0</child>
      <axis>
        <xyz>0 0 1</xyz>
        <dynamics>
          <damping>0.5</damping>
        </dynamics>
      </axis>
    </joint>
    <plugin
        filename="gz-sim-joint-position-controller-system"
        name="gz::sim::systems::JointPositionController">
      <joint_name>joint_yaw</joint_name>
      <topic>joint_cmd</topic>
      <p_gain>1</p_gain>
      <i_gain>0.1</i_gain>
      <d_gain>0.01</d_gain>
      <i_max>1</i_max>
      <i_min>-1</i_min>
      <cmd_max>1000</cmd_max>
      <cmd_min>-1000</cmd_min>
    </plugin>

    <!-- Plugin -->
    <!-- <plugin filename="GimbalPlugin" name="proto_gazebo::GimbalPlugin"> -->
    <!-- </plugin> -->
  </model>
</sdf>
